root@09f3def55e3b:/app# python -m backend.scripts.manage_db seed-reference
Seeding reference data (currencies)...
INFO:backend.scripts.seed_reference_data:Created fiat currency USD.
INFO:backend.scripts.seed_reference_data:Created crypto currency BTC.
Traceback (most recent call last):
  File "/usr/local/lib/python3.10/site-packages/sqlalchemy/engine/base.py", line 1971, in _exec_single_context
    self.dialect.do_execute(
  File "/usr/local/lib/python3.10/site-packages/sqlalchemy/engine/default.py", line 919, in do_execute
    cursor.execute(statement, parameters)
psycopg2.errors.ForeignKeyViolation: insert or update on table "fiat_currencies" violates foreign key constraint "fiat_currencies_country_id_fkey"
DETAIL:  Key (country_id)=(1) is not present in table "countries".


The above exception was the direct cause of the following exception:

Traceback (most recent call last):
  File "/usr/local/lib/python3.10/runpy.py", line 196, in _run_module_as_main
    return _run_code(code, main_globals, None,
  File "/usr/local/lib/python3.10/runpy.py", line 86, in _run_code
    exec(code, run_globals)
  File "/app/backend/scripts/manage_db.py", line 45, in <module>
    cli()
  File "/usr/local/lib/python3.10/site-packages/click/core.py", line 1161, in __call__
    return self.main(*args, **kwargs)
  File "/usr/local/lib/python3.10/site-packages/click/core.py", line 1082, in main
    rv = self.invoke(ctx)
  File "/usr/local/lib/python3.10/site-packages/click/core.py", line 1697, in invoke
    return _process_result(sub_ctx.command.invoke(sub_ctx))
  File "/usr/local/lib/python3.10/site-packages/click/core.py", line 1443, in invoke
    return ctx.invoke(self.callback, **ctx.params)
  File "/usr/local/lib/python3.10/site-packages/click/core.py", line 788, in invoke
    return __callback(*args, **kwargs)
  File "/app/backend/scripts/manage_db.py", line 41, in seed_reference
    seed_reference_main()
  File "/app/backend/scripts/seed_reference_data.py", line 40, in seed_reference_data
    session.commit()
  File "/usr/local/lib/python3.10/site-packages/sqlalchemy/orm/session.py", line 1972, in commit
    trans.commit(_to_root=True)
  File "<string>", line 2, in commit
  File "/usr/local/lib/python3.10/site-packages/sqlalchemy/orm/state_changes.py", line 139, in _go
    ret_value = fn(self, *arg, **kw)
  File "/usr/local/lib/python3.10/site-packages/sqlalchemy/orm/session.py", line 1257, in commit
    self._prepare_impl()
  File "<string>", line 2, in _prepare_impl
  File "/usr/local/lib/python3.10/site-packages/sqlalchemy/orm/state_changes.py", line 139, in _go
    ret_value = fn(self, *arg, **kw)
  File "/usr/local/lib/python3.10/site-packages/sqlalchemy/orm/session.py", line 1232, in _prepare_impl
    self.session.flush()
  File "/usr/local/lib/python3.10/site-packages/sqlalchemy/orm/session.py", line 4296, in flush
    self._flush(objects)
  File "/usr/local/lib/python3.10/site-packages/sqlalchemy/orm/session.py", line 4431, in _flush
    with util.safe_reraise():
  File "/usr/local/lib/python3.10/site-packages/sqlalchemy/util/langhelpers.py", line 146, in __exit__
    raise exc_value.with_traceback(exc_tb)
  File "/usr/local/lib/python3.10/site-packages/sqlalchemy/orm/session.py", line 4392, in _flush
    flush_context.execute()
  File "/usr/local/lib/python3.10/site-packages/sqlalchemy/orm/unitofwork.py", line 466, in execute
    rec.execute(self)
  File "/usr/local/lib/python3.10/site-packages/sqlalchemy/orm/unitofwork.py", line 642, in execute
    util.preloaded.orm_persistence.save_obj(
  File "/usr/local/lib/python3.10/site-packages/sqlalchemy/orm/persistence.py", line 93, in save_obj
    _emit_insert_statements(
  File "/usr/local/lib/python3.10/site-packages/sqlalchemy/orm/persistence.py", line 1233, in _emit_insert_statements
    result = connection.execute(
  File "/usr/local/lib/python3.10/site-packages/sqlalchemy/engine/base.py", line 1422, in execute
    return meth(
  File "/usr/local/lib/python3.10/site-packages/sqlalchemy/sql/elements.py", line 514, in _execute_on_connection
    return connection._execute_clauseelement(
  File "/usr/local/lib/python3.10/site-packages/sqlalchemy/engine/base.py", line 1644, in _execute_clauseelement
    ret = self._execute_context(
  File "/usr/local/lib/python3.10/site-packages/sqlalchemy/engine/base.py", line 1850, in _execute_context
    return self._exec_single_context(
  File "/usr/local/lib/python3.10/site-packages/sqlalchemy/engine/base.py", line 1990, in _exec_single_context
    self._handle_dbapi_exception(
  File "/usr/local/lib/python3.10/site-packages/sqlalchemy/engine/base.py", line 2357, in _handle_dbapi_exception
    raise sqlalchemy_exception.with_traceback(exc_info[2]) from e
  File "/usr/local/lib/python3.10/site-packages/sqlalchemy/engine/base.py", line 1971, in _exec_single_context
    self.dialect.do_execute(
  File "/usr/local/lib/python3.10/site-packages/sqlalchemy/engine/default.py", line 919, in do_execute
    cursor.execute(statement, parameters)
sqlalchemy.exc.IntegrityError: (psycopg2.errors.ForeignKeyViolation) insert or update on table "fiat_currencies" violates foreign key constraint "fiat_currencies_country_id_fkey"
DETAIL:  Key (country_id)=(1) is not present in table "countries".

[SQL: INSERT INTO fiat_currencies (country_id, currency_name, currency_code, public_name, description, access) VALUES (%(country_id)s, %(currency_name)s, %(currency_code)s, %(public_name)s, %(description)s, %(access)s) RETURNING fiat_currencies.id]
[parameters: {'country_id': 1, 'currency_name': 'US Dollar', 'currency_code': 'USD', 'public_name': 'US Dollar', 'description': 'Default fiat currency', 'access': True}]
(Background on this error at: https://sqlalche.me/e/20/gkpj)
